Workbook

Sheet WPI_RAW_DATA
A1: COMM_NAME | B1: COMM_CODE | C1: COMM_WT | D1: INDX042012 | E1: INDX052012 | F1: INDX062012 | G1: INDX072012 | H1: INDX082012 | I1: INDX092012 | J1: INDX102012 | K1: INDX112012 | L1: INDX122012 | M1: INDX012013 | N1: INDX022013 | O1: INDX032013 | P1: INDX042013 | Q1: INDX052013 | R1: INDX062013 | S1: INDX072013 | T1: INDX082013 | U1: INDX092013 | V1: INDX102013 | W1: INDX112013 | X1: INDX122013 | Y1: INDX012014 | Z1: INDX022014 | AA1: INDX032014 | AB1: INDX042014 | AC1: INDX052014 | AD1: INDX062014 | AE1: INDX072014 | AF1: INDX082014 | AG1: INDX092014 | AH1: INDX102014 | AI1: INDX112014 | AJ1: INDX122014 | AK1: INDX012015 | AL1: INDX022015 | AM1: INDX032015 | AN1: INDX042015 | AO1: INDX052015 | AP1: INDX062015 | AQ1: INDX072015 | AR1: INDX082015 | AS1: INDX092015 | AT1: INDX102015 | AU1: INDX112015 | AV1: INDX122015 | AW1: INDX012016 | AX1: INDX022016 | AY1: INDX032016 | AZ1: INDX042016 | BA1: INDX052016 | BB1: INDX062016 | BC1: INDX072016 | BD1: INDX082016 | BE1: INDX092016 | BF1: INDX102016 | BG1: INDX112016 | BH1: INDX122016 | BI1: INDX012017 | BJ1: INDX022017 | BK1: INDX032017 | BL1: INDX042017 | BM1: INDX052017 | BN1: INDX062017 | BO1: INDX072017 | BP1: INDX082017 | BQ1: INDX092017 | BR1: INDX102017 | BS1: INDX112017 | BT1: INDX122017 | BU1: INDX012018 | BV1: INDX022018 | BW1: INDX032018 | BX1: INDX042018 | BY1: INDX052018 | BZ1: INDX062018 | CA1: INDX072018 | CB1: INDX082018 | CC1: INDX092018 | CD1: INDX102018 | CE1: INDX112018 | CF1: INDX122018 | CG1: INDX012019 | CH1: INDX022019 | CI1: INDX032019 | CJ1: INDX042019 | CK1: INDX052019 | CL1: INDX062019 | CM1: INDX072019 | CN1: INDX082019 | CO1: INDX092019 | CP1: INDX102019 | CQ1: INDX112019 | CR1: INDX122019 | CS1: INDX012020 | CT1: INDX022020 | CU1: INDX032020 | CV1: INDX042020 | CW1: INDX052020 | CX1: INDX062020 | CY1: INDX072020 | CZ1: INDX082020 | DA1: INDX092020 | DB1: INDX102020 | DC1: INDX112020 | DD1: INDX122020 | DE1: INDX012021 | DF1: INDX022021 | DG1: INDX032021 | DH1: INDX042021 | DI1: INDX052021 | DJ1: INDX062021 | DK1: INDX072021 | DL1: INDX082021 | DM1: INDX092021 | DN1: INDX102021 | DO1: INDX112021 | DP1: INDX122021 | DQ1: INDX012022 | DR1: INDX022022 | DS1: INDX032022 | DT1: INDX042022 | DU1: INDX052022 | DV1: INDX062022 | DW1: INDX072022 | DX1: INDX082022 | DY1: INDX092022 | DZ1: INDX102022 | EA1: INDX112022 | EB1: INDX122022 | EC1: INDX012023 | ED1: INDX022023 | EE1: INDX032023 | EF1: INDX042023 | EG1: INDX052023 | EH1: INDX062023 | EI1: INDX072023 | EJ1: INDX082023 | EK1: INDX092023 | EL1: INDX102023
A2: Bajra | B2: 1101010104 | C2: 0.08637 | D2: 107.7 | E2: 109.3 | F2: 107 | G2: 113.9 | H2: 120.7 | I2: 121.7 | J2: 114.8 | K2: 120.4 | L2: 127.7 | M2: 131.6 | N2: 132.7 | O2: 132.5 | P2: 136.4 | Q2: 137.6 | R2: 136.9 | S2: 135.3 | T2: 131 | U2: 130.9 | V2: 129.7 | W2: 129.5 | X2: 131.1 | Y2: 132.3 | Z2: 131.5 | AA2: 133.6 | AB2: 134.4 | AC2: 134.6 | AD2: 132.5 | AE2: 134.4 | AF2: 133.2 | AG2: 133.9 | AH2: 129.3 | AI2: 125.6 | AJ2: 123.9 | AK2: 125 | AL2: 123.2 | AM2: 124.8 | AN2: 127.3 | AO2: 126.7 | AP2: 125.2 | AQ2: 124.3 | AR2: 127.4 | AS2: 132.2 | AT2: 132.7 | AU2: 135.3 | AV2: 139.2 | AW2: 142.9 | AX2: 144.2 | AY2: 147.7 | AZ2: 155.8 | BA2: 162.6 | BB2: 158.7 | BC2: 159.6 | BD2: 159.3 | BE2: 155.1 | BF2: 148.1 | BG2: 151 | BH2: 154.7 | BI2: 151.9 | BJ2: 151.3 | BK2: 152.6 | BL2: 153.8 | BM2: 153.2 | BN2: 149.7 | BO2: 145.4 | BP2: 143.8 | BQ2: 139.4 | BR2: 132.9 | BS2: 130.2 | BT2: 133.9 | BU2: 131.7 | BV2: 127.9 | BW2: 126.8 | BX2: 127 | BY2: 128.1 | BZ2: 129.5 | CA2: 132.9 | CB2: 138.2 | CC2: 141.7 | CD2: 148.6 | CE2: 161.7 | CF2: 165.1 | CG2: 171.2 | CH2: 178.3 | CI2: 182 | CJ2: 188 | CK2: 194.7 | CL2: 195.3 | CM2: 199.6 | CN2: 200.4 | CO2: 195.9 | CP2: 184.9 | CQ2: 188.4 | CR2: 194.7 | CS2: 201.6 | CT2: 193.7 | CU2: 187.5 | CV2: 188.9 | CW2: 185 | CX2: 176.1 | CY2: 167.3 | CZ2: 161.1 | DA2: 155.7 | DB2: 155.4 | DC2: 154.2 | DD2: 150 | DE2: 148.3 | DF2: 145.7 | DG2: 146.9 | DH2: 146.6 | DI2: 149.1 | DJ2: 150.1 | DK2: 153.9 | DL2: 161.1 | DM2: 166.4 | DN2: 164.8 | DO2: 172.6 | DP2: 183.4 | DQ2: 183.2 | DR2: 187.7 | DS2: 196.4 | DT2: 205.4 | DU2: 209.3 | DV2: 207 | DW2: 208 | DX2: 214.3 | DY2: 212.8 | DZ2: 201.5 | EA2: 209.7 | EB2: 219.2 | EC2: 224.1 | ED2: 219.6 | EE2: 225.1 | EF2: 229.6 | EG2: 229.4 | EH2: 226.7 | EI2: 226.9 | EJ2: 225.9 | EK2: 225.7 | EL2: 231.5
A3: Moong | B3: 1101010203 | C3: 0.07088 | D3: 96.3 | E3: 96 | F3: 96.6 | G3: 103.6 | H3: 108.7 | I3: 108.4 | J3: 112.2 | K3: 113.5 | L3: 115.4 | M3: 116.9 | N3: 117.1 | O3: 118.3 | P3: 120 | Q3: 118.9 | R3: 119 | S3: 118 | T3: 113.9 | U3: 117.5 | V3: 122.9 | W3: 126.4 | X3: 126.7 | Y3: 126.5 | Z3: 129.3 | AA3: 132.6 | AB3: 135.5 | AC3: 137.8 | AD3: 136.8 | AE3: 142.5 | AF3: 142.2 | AG3: 141.2 | AH3: 144.6 | AI3: 148.5 | AJ3: 153.9 | AK3: 159.1 | AL3: 155.7 | AM3: 150.7 | AN3: 151.4 | AO3: 155.7 | AP3: 170.2 | AQ3: 165.3 | AR3: 164.8 | AS3: 167.5 | AT3: 173.5 | AU3: 178.1 | AV3: 168.8 | AW3: 167.1 | AX3: 161 | AY3: 158.7 | AZ3: 162.2 | BA3: 161.9 | BB3: 155.4 | BC3: 150.4 | BD3: 143.5 | BE3: 134.7 | BF3: 131.6 | BG3: 127.4 | BH3: 122.7 | BI3: 119.7 | BJ3: 116.9 | BK3: 115.4 | BL3: 120.8 | BM3: 120.1 | BN3: 116.8 | BO3: 113 | BP3: 112.6 | BQ3: 112.9 | BR3: 111.5 | BS3: 109.8 | BT3: 110.7 | BU3: 112.2 | BV3: 113 | BW3: 114.1 | BX3: 111.5 | BY3: 113 | BZ3: 112.4 | CA3: 115 | CB3: 118.9 | CC3: 119.8 | CD3: 118.1 | CE3: 121.6 | CF3: 123 | CG3: 125.8 | CH3: 128.2 | CI3: 127.8 | CJ3: 128.2 | CK3: 130.9 | CL3: 135.6 | CM3: 137.1 | CN3: 137.2 | CO3: 138.7 | CP3: 139.7 | CQ3: 146.7 | CR3: 149.6 | CS3: 151.3 | CT3: 156.6 | CU3: 162 | CV3: 174.2 | CW3: 179.7 | CX3: 176.1 | CY3: 173.6 | CZ3: 170.4 | DA3: 164.3 | DB3: 162.6 | DC3: 165.1 | DD3: 168.5 | DE3: 166.7 | DF3: 169.7 | DG3: 169.2 | DH3: 169.7 | DI3: 169.6 | DJ3: 167.4 | DK3: 163.5 | DL3: 162.5 | DM3: 164.9 | DN3: 166.3 | DO3: 164.7 | DP3: 165.1 | DQ3: 164.1 | DR3: 166.1 | DS3: 168.8 | DT3: 167.7 | DU3: 166.3 | DV3: 165.1 | DW3: 166.2 | DX3: 167.6 | DY3: 166.2 | DZ3: 166.2 | EA3: 165.7 | EB3: 168.2 | EC3: 167.7 | ED3: 167.8 | EE3: 172.8 | EF3: 180.8 | EG3: 178.6 | EH3: 184.8 | EI3: 188.7 | EJ3: 189.4 | EK3: 199.7 | EL3: 205.6
A4: Masur | B4: 1101010204 | C4: 0.05299 | D4: 102.5 | E4: 107.4 | F4: 109.7 | G4: 115.2 | H4: 119.2 | I4: 119 | J4: 118.6 | K4: 118.1 | L4: 117.4 | M4: 119.8 | N4: 120.1 | O4: 119.5 | P4: 126.1 | Q4: 127.1 | R4: 130.6 | S4: 131.5 | T4: 132.2 | U4: 132.7 | V4: 130.9 | W4: 134.1 | X4: 135.6 | Y4: 136.4 | Z4: 136.6 | AA4: 140.8 | AB4: 143.3 | AC4: 145.5 | AD4: 146.2 | AE4: 147.9 | AF4: 150.2 | AG4: 152.6 | AH4: 152.1 | AI4: 153.9 | AJ4: 157.5 | AK4: 166.8 | AL4: 166.2 | AM4: 164.9 | AN4: 165.1 | AO4: 177 | AP4: 186.3 | AQ4: 188.4 | AR4: 195.6 | AS4: 195.1 | AT4: 197 | AU4: 198.8 | AV4: 195.5 | AW4: 190.5 | AX4: 184 | AY4: 182.3 | AZ4: 186.8 | BA4: 190.2 | BB4: 191 | BC4: 190.7 | BD4: 185.6 | BE4: 182 | BF4: 179.2 | BG4: 176.8 | BH4: 169.6 | BI4: 161.1 | BJ4: 156.2 | BK4: 154 | BL4: 155.3 | BM4: 148.5 | BN4: 144.5 | BO4: 137.5 | BP4: 136 | BQ4: 138.3 | BR4: 133.8 | BS4: 130.9 | BT4: 130.3 | BU4: 126.7 | BV4: 122.1 | BW4: 120.6 | BX4: 120.8 | BY4: 120.7 | BZ4: 117.8 | CA4: 117.9 | CB4: 121 | CC4: 121.8 | CD4: 121.7 | CE4: 121.2 | CF4: 124.6 | CG4: 127.5 | CH4: 129.5 | CI4: 130.1 | CJ4: 131.8 | CK4: 134.9 | CL4: 137.1 | CM4: 137.5 | CN4: 137.3 | CO4: 137.3 | CP4: 137 | CQ4: 140.5 | CR4: 143.2 | CS4: 147.9 | CT4: 147.1 | CU4: 146 | CV4: 149.7 | CW4: 150.8 | CX4: 155.1 | CY4: 157.5 | CZ4: 158 | DA4: 159 | DB4: 162.8 | DC4: 166.3 | DD4: 163.8 | DE4: 165.4 | DF4: 166.3 | DG4: 168.4 | DH4: 171.9 | DI4: 176.1 | DJ4: 179.6 | DK4: 179.9 | DL4: 184 | DM4: 197.3 | DN4: 203.3 | DO4: 203.4 | DP4: 201.7 | DQ4: 202.9 | DR4: 204.9 | DS4: 205.5 | DT4: 202.8 | DU4: 202.5 | DV4: 200.6 | DW4: 202.1 | DX4: 204.4 | DY4: 199.7 | DZ4: 199.8 | EA4: 202.1 | EB4: 199.8 | EC4: 199 | ED4: 196.3 | EE4: 194.6 | EF4: 192.1 | EG4: 188.1 | EH4: 187.7 | EI4: 186.6 | EJ4: 186.9 | EK4: 192.6 | EL4: 189.5
A5: Peas/Chawali | B5: 1101010206 | C5: 0.02444 | D5: 113.2 | E5: 123.1 | F5: 134.3 | G5: 147.4 | H5: 143.3 | I5: 153.8 | J5: 146.6 | K5: 131.8 | L5: 124.8 | M5: 118.4 | N5: 113 | O5: 123.2 | P5: 136.2 | Q5: 139.7 | R5: 153.1 | S5: 151.7 | T5: 147.4 | U5: 157.1 | V5: 157 | W5: 150.2 | X5: 131.9 | Y5: 103.4 | Z5: 105.8 | AA5: 116.7 | AB5: 129.9 | AC5: 135.6 | AD5: 139.8 | AE5: 145.7 | AF5: 147.2 | AG5: 146.4 | AH5: 147.3 | AI5: 136.5 | AJ5: 119.1 | AK5: 113.6 | AL5: 106.5 | AM5: 124.7 | AN5: 126.1 | AO5: 136.9 | AP5: 150 | AQ5: 142.1 | AR5: 139.7 | AS5: 148.2 | AT5: 142.7 | AU5: 140.3 | AV5: 122.8 | AW5: 120.5 | AX5: 112.4 | AY5: 112.4 | AZ5: 136.6 | BA5: 146.3 | BB5: 158.2 | BC5: 156.6 | BD5: 147.4 | BE5: 147.4 | BF5: 153.7 | BG5: 152.2 | BH5: 134.7 | BI5: 120.2 | BJ5: 119.7 | BK5: 122.2 | BL5: 133.3 | BM5: 136.1 | BN5: 130.2 | BO5: 137.6 | BP5: 141.4 | BQ5: 142.3 | BR5: 142.4 | BS5: 141.2 | BT5: 137.8 | BU5: 130 | BV5: 127.3 | BW5: 129 | BX5: 145.5 | BY5: 149.9 | BZ5: 150.5 | CA5: 154 | CB5: 158.4 | CC5: 157.6 | CD5: 183 | CE5: 203.9 | CF5: 189.9 | CG5: 167.7 | CH5: 155.7 | CI5: 168.2 | CJ5: 179 | CK5: 185.1 | CL5: 189.9 | CM5: 190.7 | CN5: 194.9 | CO5: 199.9 | CP5: 200.6 | CQ5: 202.4 | CR5: 177.4 | CS5: 182.4 | CT5: 182.3 | CU5: 180.1 | CV5: 187.8 | CW5: 194.9 | CX5: 199.6 | CY5: 200 | CZ5: 202.4 | DA5: 205.1 | DB5: 213.5 | DC5: 230.2 | DD5: 187.1 | DE5: 172.9 | DF5: 178.6 | DG5: 188.7 | DH5: 217.7 | DI5: 219 | DJ5: 216.5 | DK5: 214 | DL5: 217.6 | DM5: 219 | DN5: 209.7 | DO5: 237 | DP5: 199.2 | DQ5: 191.4 | DR5: 195.1 | DS5: 187.9 | DT5: 209.6 | DU5: 223.5 | DV5: 220.6 | DW5: 218.3 | DX5: 230.1 | DY5: 235.7 | DZ5: 250.2 | EA5: 223.1 | EB5: 175.9 | EC5: 160.4 | ED5: 160.2 | EE5: 166.9 | EF5: 195.5 | EG5: 199.5 | EH5: 196 | EI5: 215.9 | EJ5: 219.8 | EK5: 227.4 | EL5: 237.6
A6: Cauliflower | B6: 1101020108 | C6: 0.16697 | D6: 119.1 | E6: 0 | F6: 0 | G6: 0 | H6: 0 | I6: 134.6 | J6: 129.4 | K6: 101.7 | L6: 92.6 | M6: 103.1 | N6: 99.6 | O6: 103.6 | P6: 109 | Q6: 0 | R6: 0 | S6: 0 | T6: 0 | U6: 146.4 | V6: 162.9 | W6: 178.3 | X6: 119 | Y6: 99.6 | Z6: 91.7 | AA6: 97.9 | AB6: 105.8 | AC6: 0 | AD6: 0 | AE6: 0 | AF6: 0 | AG6: 162 | AH6: 148.3 | AI6: 129.7 | AJ6: 119.7 | AK6: 110.7 | AL6: 102 | AM6: 102.7 | AN6: 101.6 | AO6: 0 | AP6: 0 | AQ6: 0 | AR6: 0 | AS6: 123.6 | AT6: 121 | AU6: 122 | AV6: 126.1 | AW6: 111.9 | AX6: 93.5 | AY6: 87.5 | AZ6: 90.4 | BA6: 0 | BB6: 0 | BC6: 0 | BD6: 0 | BE6: 154.1 | BF6: 171.3 | BG6: 145.4 | BH6: 110.4 | BI6: 88 | BJ6: 80.8 | BK6: 104.8 | BL6: 115.2 | BM6: 0 | BN6: 0 | BO6: 0 | BP6: 0 | BQ6: 118.8 | BR6: 142.2 | BS6: 141.5 | BT6: 106.2 | BU6: 92 | BV6: 76.6 | BW6: 68.5 | BX6: 80.8 | BY6: 0 | BZ6: 0 | CA6: 0 | CB6: 0 | CC6: 174.9 | CD6: 178.5 | CE6: 161 | CF6: 132.3 | CG6: 130.5 | CH6: 114 | CI6: 149.2 | CJ6: 178.9 | CK6: 0 | CL6: 0 | CM6: 0 | CN6: 0 | CO6: 191.1 | CP6: 227.7 | CQ6: 246.1 | CR6: 196.6 | CS6: 198.3 | CT6: 154.7 | CU6: 142.9 | CV6: 160.7 | CW6: 0 | CX6: 0 | CY6: 0 | CZ6: 0 | DA6: 226.4 | DB6: 239.6 | DC6: 215.1 | DD6: 162.2 | DE6: 141.1 | DF6: 137.3 | DG6: 139.1 | DH6: 159.7 | DI6: 0 | DJ6: 0 | DK6: 0 | DL6: 0 | DM6: 231.2 | DN6: 250.1 | DO6: 293.1 | DP6: 282 | DQ6: 245.7 | DR6: 208.7 | DS6: 184.5 | DT6: 209.2 | DU6: 0 | DV6: 0 | DW6: 0 | DX6: 0 | DY6: 291.7 | DZ6: 329 | EA6: 234.2 | EB6: 164.3 | EC6: 161.1 | ED6: 148.4 | EE6: 163.5 | EF6: 176.9 | EG6: 0 | EH6: 0 | EI6: 0 | EJ6: 0 | EK6: 230.3 | EL6: 244.6
A7: Okra (Lady finger) | B7: 1101020110 | C7: 0.14592 | D7: 152.2 | E7: 92.6 | F7: 90.3 | G7: 87 | H7: 78 | I7: 75.1 | J7: 89.3 | K7: 94.2 | L7: 112.4 | M7: 112.7 | N7: 117.1 | O7: 115.8 | P7: 99.6 | Q7: 61.5 | R7: 69.8 | S7: 86.5 | T7: 89.7 | U7: 91.6 | V7: 109.6 | W7: 142.8 | X7: 144.8 | Y7: 142.4 | Z7: 143.6 | AA7: 134.5 | AB7: 94 | AC7: 61.3 | AD7: 61.5 | AE7: 89.9 | AF7: 84 | AG7: 85.8 | AH7: 83.4 | AI7: 106.5 | AJ7: 125.4 | AK7: 137.8 | AL7: 109.2 | AM7: 110.2 | AN7: 99.8 | AO7: 74.4 | AP7: 80.4 | AQ7: 77.1 | AR7: 65.1 | AS7: 65.4 | AT7: 83.8 | AU7: 94.7 | AV7: 117.4 | AW7: 125.3 | AX7: 117 | AY7: 95.6 | AZ7: 84.8 | BA7: 79.7 | BB7: 73 | BC7: 79.2 | BD7: 82 | BE7: 80.8 | BF7: 86.5 | BG7: 74 | BH7: 89.9 | BI7: 112.8 | BJ7: 122.1 | BK7: 115.3 | BL7: 99 | BM7: 97.3 | BN7: 87.4 | BO7: 104.9 | BP7: 129 | BQ7: 98.5 | BR7: 132.9 | BS7: 149.2 | BT7: 158.1 | BU7: 160.2 | BV7: 151.3 | BW7: 154.4 | BX7: 114.8 | BY7: 80.2 | BZ7: 83.3 | CA7: 114.7 | CB7: 128.7 | CC7: 110.3 | CD7: 117.1 | CE7: 108.3 | CF7: 135.6 | CG7: 166.2 | CH7: 173.3 | CI7: 168.5 | CJ7: 142.4 | CK7: 119.6 | CL7: 87 | CM7: 91.8 | CN7: 87.6 | CO7: 80.3 | CP7: 110.2 | CQ7: 156.7 | CR7: 196.2 | CS7: 191.9 | CT7: 191.1 | CU7: 173 | CV7: 156 | CW7: 97.5 | CX7: 87.6 | CY7: 82.6 | CZ7: 93.7 | DA7: 131.6 | DB7: 161 | DC7: 131.4 | DD7: 152.2 | DE7: 194.1 | DF7: 225.9 | DG7: 190.4 | DH7: 149.7 | DI7: 120.5 | DJ7: 129.4 | DK7: 153 | DL7: 113 | DM7: 97.8 | DN7: 129.2 | DO7: 195.6 | DP7: 274.4 | DQ7: 279.8 | DR7: 273.7 | DS7: 212.1 | DT7: 179.6 | DU7: 106.6 | DV7: 88.7 | DW7: 102.8 | DX7: 113.7 | DY7: 125.3 | DZ7: 144.2 | EA7: 132.6 | EB7: 152.6 | EC7: 246.8 | ED7: 266.9 | EE7: 263.4 | EF7: 212 | EG7: 147 | EH7: 121.7 | EI7: 177.9 | EJ7: 130.6 | EK7: 94 | EL7: 123.5
A8: Beans | B8: 1101020118 | C8: 0.08309 | D8: 140.4 | E8: 137.4 | F8: 138.3 | G8: 111.2 | H8: 113.3 | I8: 90.3 | J8: 96.5 | K8: 113.1 | L8: 113.6 | M8: 106.4 | N8: 108.9 | O8: 136.9 | P8: 172 | Q8: 179.2 | R8: 181.8 | S8: 119.1 | T8: 112.3 | U8: 131.9 | V8: 125.1 | W8: 99.5 | X8: 117 | Y8: 109.2 | Z8: 103.8 | AA8: 109.5 | AB8: 116.7 | AC8: 148.8 | AD8: 153.1 | AE8: 135.3 | AF8: 110.5 | AG8: 90.3 | AH8: 127.5 | AI8: 129 | AJ8: 127.9 | AK8: 99.5 | AL8: 112.4 | AM8: 107.6 | AN8: 124.2 | AO8: 176.5 | AP8: 137.3 | AQ8: 134.8 | AR8: 134.8 | AS8: 134.8 | AT8: 134.8 | AU8: 134.8 | AV8: 134.8 | AW8: 134.8 | AX8: 134.8 | AY8: 134.8 | AZ8: 170.3 | BA8: 203.5 | BB8: 210.2 | BC8: 110.7 | BD8: 88.9 | BE8: 110.9 | BF8: 142 | BG8: 125.3 | BH8: 125.3 | BI8: 116.9 | BJ8: 140.1 | BK8: 175.4 | BL8: 180.2 | BM8: 187.3 | BN8: 182.6 | BO8: 154.7 | BP8: 136.7 | BQ8: 143.5 | BR8: 161.5 | BS8: 148.6 | BT8: 110.6 | BU8: 92.6 | BV8: 71.6 | BW8: 75.4 | BX8: 83 | BY8: 99.3 | BZ8: 114.2 | CA8: 99 | CB8: 84.5 | CC8: 100.9 | CD8: 119.9 | CE8: 125.7 | CF8: 116.3 | CG8: 113.1 | CH8: 105.3 | CI8: 122 | CJ8: 134.1 | CK8: 142.8 | CL8: 157.4 | CM8: 150.4 | CN8: 143.1 | CO8: 134 | CP8: 142.1 | CQ8: 134.9 | CR8: 136.1 | CS8: 145.2 | CT8: 117.8 | CU8: 108.4 | CV8: 146.5 | CW8: 149.3 | CX8: 143.9 | CY8: 108.4 | CZ8: 124.3 | DA8: 173.1 | DB8: 196 | DC8: 166.5 | DD8: 134.4 | DE8: 137.7 | DF8: 165.8 | DG8: 147.2 | DH8: 152.1 | DI8: 152.3 | DJ8: 181.2 | DK8: 141.1 | DL8: 129.9 | DM8: 130.2 | DN8: 158.7 | DO8: 172.5 | DP8: 200.5 | DQ8: 181.3 | DR8: 148.6 | DS8: 133.4 | DT8: 152.9 | DU8: 184.2 | DV8: 188.5 | DW8: 198.8 | DX8: 204.5 | DY8: 200.1 | DZ8: 185 | EA8: 163.4 | EB8: 121.5 | EC8: 129.5 | ED8: 143.4 | EE8: 166.3 | EF8: 223.3 | EG8: 207.1 | EH8: 225.1 | EI8: 248.2 | EJ8: 220.5 | EK8: 172.8 | EL8: 224.5
A9: Drumstick | B9: 1101020120 | C9: 0.01823 | D9: 59 | E9: 59.5 | F9: 90.9 | G9: 94.1 | H9: 74.3 | I9: 64.8 | J9: 81.9 | K9: 114 | L9: 227.1 | M9: 189.2 | N9: 122.5 | O9: 69.3 | P9: 61.5 | Q9: 69.5 | R9: 112 | S9: 134.3 | T9: 115.8 | U9: 115.3 | V9: 203 | W9: 256.9 | X9: 276.1 | Y9: 273.4 | Z9: 178.7 | AA9: 88.3 | AB9: 89.7 | AC9: 94.4 | AD9: 182.4 | AE9: 133 | AF9: 122.8 | AG9: 147.7 | AH9: 172.9 | AI9: 276 | AJ9: 352.5 | AK9: 379.2 | AL9: 204.1 | AM9: 121.5 | AN9: 113.3 | AO9: 151.8 | AP9: 158.2 | AQ9: 129.7 | AR9: 129.7 | AS9: 129.7 | AT9: 129.7 | AU9: 129.7 | AV9: 129.7 | AW9: 129.7 | AX9: 129.7 | AY9: 129.7 | AZ9: 76.5 | BA9: 102.8 | BB9: 163 | BC9: 139.7 | BD9: 91 | BE9: 91.9 | BF9: 103 | BG9: 138.6 | BH9: 214 | BI9: 229.6 | BJ9: 131.2 | BK9: 89 | BL9: 76.2 | BM9: 112.8 | BN9: 125.8 | BO9: 162.9 | BP9: 160.6 | BQ9: 176.8 | BR9: 256.2 | BS9: 254.2 | BT9: 380.2 | BU9: 315.7 | BV9: 218.5 | BW9: 112.5 | BX9: 97.1 | BY9: 103 | BZ9: 134 | CA9: 148.6 | CB9: 117.1 | CC9: 112.7 | CD9: 128.7 | CE9: 199.1 | CF9: 219.3 | CG9: 269.8 | CH9: 227.5 | CI9: 106.3 | CJ9: 79.5 | CK9: 95.9 | CL9: 120.4 | CM9: 192.5 | CN9: 161.8 | CO9: 156.8 | CP9: 178.7 | CQ9: 321.4 | CR9: 601.4 | CS9: 472 | CT9: 248.9 | CU9: 127.3 | CV9: 105.3 | CW9: 98.7 | CX9: 138.8 | CY9: 157.1 | CZ9: 173.6 | DA9: 228.7 | DB9: 228.2 | DC9: 255.7 | DD9: 208.2 | DE9: 345.8 | DF9: 307.7 | DG9: 232.5 | DH9: 102.6 | DI9: 103.2 | DJ9: 194 | DK9: 181.9 | DL9: 147.2 | DM9: 161.5 | DN9: 251.6 | DO9: 335.6 | DP9: 581.4 | DQ9: 698.3 | DR9: 525.5 | DS9: 275.8 | DT9: 129.9 | DU9: 150.9 | DV9: 208.4 | DW9: 153.3 | DX9: 159.9 | DY9: 223.7 | DZ9: 310.6 | EA9: 374.4 | EB9: 485.2 | EC9: 480.1 | ED9: 407.5 | EE9: 257.6 | EF9: 140.1 | EG9: 142.5 | EH9: 192.7 | EI9: 166.5 | EJ9: 138.3 | EK9: 102.7 | EL9: 258.2
A10: Orange | B10: 1101020204 | C10: 0.12653 | D10: 107.9 | E10: 109.9 | F10: 112.2 | G10: 0 | H10: 0 | I10: 0 | J10: 0 | K10: 113.3 | L10: 109.9 | M10: 109.7 | N10: 111 | O10: 110 | P10: 110.2 | Q10: 120.1 | R10: 120.4 | S10: 0 | T10: 0 | U10: 0 | V10: 0 | W10: 108 | X10: 99.3 | Y10: 95.2 | Z10: 100.1 | AA10: 109.2 | AB10: 114 | AC10: 119.9 | AD10: 121.2 | AE10: 0 | AF10: 0 | AG10: 0 | AH10: 0 | AI10: 106.8 | AJ10: 101.4 | AK10: 106.6 | AL10: 111.8 | AM10: 112.3 | AN10: 113.3 | AO10: 114.7 | AP10: 116.4 | AQ10: 0 | AR10: 0 | AS10: 0 | AT10: 0 | AU10: 94.2 | AV10: 97.4 | AW10: 105.4 | AX10: 105.6 | AY10: 108.1 | AZ10: 124.2 | BA10: 124.6 | BB10: 130.2 | BC10: 0 | BD10: 0 | BE10: 0 | BF10: 0 | BG10: 124.5 | BH10: 122.2 | BI10: 121.7 | BJ10: 122.2 | BK10: 122.6 | BL10: 122.9 | BM10: 126.5 | BN10: 132.5 | BO10: 0 | BP10: 0 | BQ10: 0 | BR10: 0 | BS10: 125.1 | BT10: 126 | BU10: 123.3 | BV10: 123.7 | BW10: 121.2 | BX10: 123.7 | BY10: 136.1 | BZ10: 145.1 | CA10: 0 | CB10: 0 | CC10: 0 | CD10: 0 | CE10: 108.4 | CF10: 93.9 | CG10: 94.7 | CH10: 99.2 | CI10: 101.3 | CJ10: 112.3 | CK10: 117.7 | CL10: 120.1 | CM10: 0 | CN10: 0 | CO10: 0 | CP10: 0 | CQ10: 120.2 | CR10: 111.4 | CS10: 111.6 | CT10: 99 | CU10: 96.7 | CV10: 104.7 | CW10: 115 | CX10: 121 | CY10: 0 | CZ10: 0 | DA10: 0 | DB10: 0 | DC10: 130.4 | DD10: 110.8 | DE10: 117.7 | DF10: 154.4 | DG10: 186.1 | DH10: 253.8 | DI10: 285.7 | DJ10: 284.9 | DK10: 0 | DL10: 0 | DM10: 0 | DN10: 0 | DO10: 168.2 | DP10: 177.7 | DQ10: 184.7 | DR10: 201.2 | DS10: 223.6 | DT10: 254 | DU10: 259 | DV10: 265.4 | DW10: 0 | DX10: 0 | DY10: 0 | DZ10: 0 | EA10: 188.9 | EB10: 187.8 | EC10: 215.9 | ED10: 239 | EE10: 242.5 | EF10: 280.5 | EG10: 284.2 | EH10: 293.1 | EI10: 0 | EJ10: 0 | EK10: 0 | EL10: 0
A11: Cashew nut | B11: 1101020205 | C11: 0.06583 | D11: 90.3 | E11: 96.1 | F11: 96 | G11: 99.5 | H11: 103.5 | I11: 103.1 | J11: 101.5 | K11: 102.7 | L11: 101.2 | M11: 103 | N11: 104.6 | O11: 98.3 | P11: 95.8 | Q11: 96.7 | R11: 99.1 | S11: 101.9 | T11: 103.9 | U11: 106.6 | V11: 109.8 | W11: 113.5 | X11: 114.3 | Y11: 115.3 | Z11: 116.4 | AA11: 115.3 | AB11: 115.2 | AC11: 107.7 | AD11: 112.8 | AE11: 115.3 | AF11: 112.6 | AG11: 116.5 | AH11: 123.9 | AI11: 124.5 | AJ11: 122.8 | AK11: 127.8 | AL11: 131.4 | AM11: 128.5 | AN11: 126.3 | AO11: 131.7 | AP11: 132.4 | AQ11: 134.9 | AR11: 136 | AS11: 138.6 | AT11: 145.1 | AU11: 144.2 | AV11: 145.8 | AW11: 142.7 | AX11: 145.2 | AY11: 144.4 | AZ11: 145.4 | BA11: 148.5 | BB11: 150.8 | BC11: 150.5 | BD11: 154.1 | BE11: 164.8 | BF11: 166.6 | BG11: 165.6 | BH11: 169.5 | BI11: 171.7 | BJ11: 172.3 | BK11: 171.1 | BL11: 166.8 | BM11: 170.9 | BN11: 173.2 | BO11: 173.8 | BP11: 178.6 | BQ11: 179.9 | BR11: 181.3 | BS11: 177.6 | BT11: 181.6 | BU11: 183.5 | BV11: 182.6 | BW11: 181 | BX11: 177.3 | BY11: 173.7 | BZ11: 171.5 | CA11: 172.9 | CB11: 173.2 | CC11: 170.8 | CD11: 168.6 | CE11: 171.3 | CF11: 170.9 | CG11: 169.7 | CH11: 165.7 | CI11: 163.3 | CJ11: 159.2 | CK11: 156.9 | CL11: 158.8 | CM11: 157.1 | CN11: 155.2 | CO11: 158 | CP11: 160.3 | CQ11: 161.7 | CR11: 163.3 | CS11: 163.7 | CT11: 163.1 | CU11: 159.6 | CV11: 160.3 | CW11: 160.4 | CX11: 159.1 | CY11: 154.8 | CZ11: 156.8 | DA11: 156.7 | DB11: 158.5 | DC11: 161.7 | DD11: 158.8 | DE11: 164.7 | DF11: 161.8 | DG11: 162.1 | DH11: 158.3 | DI11: 154.4 | DJ11: 152.5 | DK11: 150.4 | DL11: 156.9 | DM11: 163 | DN11: 167.5 | DO11: 168.3 | DP11: 163 | DQ11: 162.3 | DR11: 160.3 | DS11: 160.8 | DT11: 161.6 | DU11: 163.2 | DV11: 161.1 | DW11: 157.1 | DX11: 154.9 | DY11: 155.1 | DZ11: 154.1 | EA11: 153.9 | EB11: 153.5 | EC11: 150.2 | ED11: 152.4 | EE11: 151.8 | EF11: 154.8 | EG11: 150.4 | EH11: 146.7 | EI11: 145.4 | EJ11: 145.7 | EK11: 146.3 | EL11: 147
A12: Grapes | B12: 1101020208 | C12: 0.04932 | D12: 88.1 | E12: 0 | F12: 0 | G12: 0 | H12: 0 | I12: 0 | J12: 93.5 | K12: 101.3 | L12: 104.1 | M12: 102.4 | N12: 94.8 | O12: 92.2 | P12: 94.2 | Q12: 0 | R12: 0 | S12: 0 | T12: 0 | U12: 0 | V12: 105.4 | W12: 107.7 | X12: 109.1 | Y12: 103.9 | Z12: 99 | AA12: 98 | AB12: 101.6 | AC12: 0 | AD12: 0 | AE12: 0 | AF12: 0 | AG12: 0 | AH12: 118.2 | AI12: 123.8 | AJ12: 121.9 | AK12: 130.5 | AL12: 120.5 | AM12: 108.1 | AN12: 110 | AO12: 0 | AP12: 0 | AQ12: 0 | AR12: 0 | AS12: 0 | AT12: 135.5 | AU12: 128.6 | AV12: 125.1 | AW12: 116.4 | AX12: 128 | AY12: 119.4 | AZ12: 108.7 | BA12: 0 | BB12: 0 | BC12: 0 | BD12: 0 | BE12: 0 | BF12: 111.5 | BG12: 113.8 | BH12: 120 | BI12: 112.8 | BJ12: 115.4 | BK12: 105.2 | BL12: 102.1 | BM12: 0 | BN12: 0 | BO12: 0 | BP12: 0 | BQ12: 0 | BR12: 122 | BS12: 123.5 | BT12: 128.6 | BU12: 119.2 | BV12: 113.7 | BW12: 111.1 | BX12: 119.2 | BY12: 0 | BZ12: 0 | CA12: 0 | CB12: 0 | CC12: 0 | CD12: 119.6 | CE12: 118.5 | CF12: 121.6 | CG12: 118.8 | CH12: 111 | CI12: 109.6 | CJ12: 118.1 | CK12: 0 | CL12: 0 | CM12: 0 | CN12: 0 | CO12: 0 | CP12: 154.5 | CQ12: 176.9 | CR12: 139.5 | CS12: 138.5 | CT12: 143 | CU12: 139.2 | CV12: 132.2 | CW12: 0 | CX12: 0 | CY12: 0 | CZ12: 0 | DA12: 0 | DB12: 120.3 | DC12: 123 | DD12: 139.8 | DE12: 142.7 | DF12: 145.1 | DG12: 132.8 | DH12: 143.4 | DI12: 0 | DJ12: 0 | DK12: 0 | DL12: 0 | DM12: 0 | DN12: 169.7 | DO12: 199.3 | DP12: 161.6 | DQ12: 159.9 | DR12: 146.3 | DS12: 149 | DT12: 159.5 | DU12: 0 | DV12: 0 | DW12: 0 | DX12: 0 | DY12: 0 | DZ12: 185.3 | EA12: 217.7 | EB12: 195.4 | EC12: 179.4 | ED12: 194.4 | EE12: 187.4 | EF12: 183.2 | EG12: 0 | EH12: 0 | EI12: 0 | EJ12: 0 | EK12: 0 | EL12: 216
A13: Litchi | B13: 1101020211 | C13: 0.02955 | D13: 0 | E13: 0 | F13: 125.7 | G13: 156.7 | H13: 0 | I13: 0 | J13: 0 | K13: 0 | L13: 0 | M13: 0 | N13: 0 | O13: 0 | P13: 0 | Q13: 0 | R13: 129.5 | S13: 147.5 | T13: 0 | U13: 0 | V13: 0 | W13: 0 | X13: 0 | Y13: 0 | Z13: 0 | AA13: 0 | AB13: 0 | AC13: 0 | AD13: 170 | AE13: 159.3 | AF13: 0 | AG13: 0 | AH13: 0 | AI13: 0 | AJ13: 0 | AK13: 0 | AL13: 0 | AM13: 0 | AN13: 0 | AO13: 0 | AP13: 161 | AQ13: 178.5 | AR13: 0 | AS13: 0 | AT13: 0 | AU13: 0 | AV13: 0 | AW13: 0 | AX13: 0 | AY13: 0 | AZ13: 0 | BA13: 0 | BB13: 181.1 | BC13: 191.2 | BD13: 0 | BE13: 0 | BF13: 0 | BG13: 0 | BH13: 0 | BI13: 0 | BJ13: 0 | BK13: 0 | BL13: 0 | BM13: 0 | BN13: 132.6 | BO13: 194.1 | BP13: 0 | BQ13: 0 | BR13: 0 | BS13: 0 | BT13: 0 | BU13: 0 | BV13: 0 | BW13: 0 | BX13: 0 | BY13: 0 | BZ13: 126.7 | CA13: 132.8 | CB13: 0 | CC13: 0 | CD13: 0 | CE13: 0 | CF13: 0 | CG13: 0 | CH13: 0 | CI13: 0 | CJ13: 0 | CK13: 0 | CL13: 135.9 | CM13: 127.5 | CN13: 0 | CO13: 0 | CP13: 0 | CQ13: 0 | CR13: 0 | CS13: 0 | CT13: 0 | CU13: 0 | CV13: 0 | CW13: 0 | CX13: 127.5 | CY13: 127.5 | CZ13: 0 | DA13: 0 | DB13: 0 | DC13: 0 | DD13: 0 | DE13: 0 | DF13: 0 | DG13: 0 | DH13: 0 | DI13: 0 | DJ13: 121.8 | DK13: 131.5 | DL13: 0 | DM13: 0 | DN13: 0 | DO13: 0 | DP13: 0 | DQ13: 0 | DR13: 0 | DS13: 0 | DT13: 0 | DU13: 0 | DV13: 148.7 | DW13: 287.7 | DX13: 0 | DY13: 0 | DZ13: 0 | EA13: 0 | EB13: 0 | EC13: 0 | ED13: 0 | EE13: 0 | EF13: 0 | EG13: 0 | EH13: 199.7 | EI13: 229 | EJ13: 0 | EK13: 0 | EL13: 0
... A348: Intraocular Lens | B348: 1322050001 | C348: 0.04941 | D348: 115 | E348: 115 | F348: 115 | G348: 115 | H348: 115 | I348: 115 | J348: 115 | K348: 115 | L348: 115 | M348: 117.1 | N348: 117.1 | O348: 117.1 | P348: 121.3 | Q348: 121.3 | R348: 121.3 | S348: 121.3 | T348: 122.2 | U348: 122.2 | V348: 122.2 | W348: 122.2 | X348: 123.1 | Y348: 123.8 | Z348: 123.8 | AA348: 123.8 | AB348: 124.9 | AC348: 124.9 | AD348: 124.9 | AE348: 124.9 | AF348: 124.9 | AG348: 124.9 | AH348: 124.9 | AI348: 124.9 | AJ348: 124.9 | AK348: 125.4 | AL348: 125.4 | AM348: 126.5 | AN348: 143.3 | AO348: 143.3 | AP348: 143.3 | AQ348: 143.3 | AR348: 144.6 | AS348: 144.6 | AT348: 144.6 | AU348: 144.6 | AV348: 145.4 | AW348: 145.4 | AX348: 145.4 | AY348: 147.3 | AZ348: 147.3 | BA348: 147.3 | BB348: 147.3 | BC348: 147.3 | BD348: 144.5 | BE348: 144.5 | BF348: 144.5 | BG348: 144.5 | BH348: 144.5 | BI348: 134.9 | BJ348: 134.9 | BK348: 138.5 | BL348: 139.1 | BM348: 139.1 | BN348: 148 | BO348: 152 | BP348: 153.5 | BQ348: 155.3 | BR348: 155.3 | BS348: 157.6 | BT348: 157.6 | BU348: 153.8 | BV348: 155.6 | BW348: 155.9 | BX348: 155.6 | BY348: 160 | BZ348: 160.4 | CA348: 154.9 | CB348: 155.1 | CC348: 160.6 | CD348: 160.6 | CE348: 160.7 | CF348: 160.3 | CG348: 160.8 | CH348: 160.9 | CI348: 160.9 | CJ348: 160.9 | CK348: 160.9 | CL348: 161.1 | CM348: 161 | CN348: 162.1 | CO348: 162.4 | CP348: 162.5 | CQ348: 162.5 | CR348: 162.5 | CS348: 162.9 | CT348: 163.2 | CU348: 163.2 | CV348: 163.2 | CW348: 165 | CX348: 167.2 | CY348: 167.3 | CZ348: 167.5 | DA348: 166.9 | DB348: 168.1 | DC348: 168.5 | DD348: 168.1 | DE348: 168.9 | DF348: 168.8 | DG348: 168.8 | DH348: 169.8 | DI348: 170.7 | DJ348: 170.7 | DK348: 171.3 | DL348: 171.3 | DM348: 172.9 | DN348: 172.9 | DO348: 172.9 | DP348: 171.1 | DQ348: 170.8 | DR348: 169.6 | DS348: 177.8 | DT348: 176.4 | DU348: 175.7 | DV348: 173.5 | DW348: 171.3 | DX348: 172 | DY348: 169.7 | DZ348: 170.5 | EA348: 168 | EB348: 168 | EC348: 167.2 | ED348: 166.7 | EE348: 166.3 | EF348: 166.3 | EG348: 163.6 | EH348: 164.5 | EI348: 164.5 | EJ348: 164.5 | EK348: 162.7 | EL348: 163.2
A349: IV FOOD INDEX | B349: 2000000000 | D349: 105.9 | E349: 106.5 | F349: 108.4 | G349: 110.4 | H349: 111.1 | I349: 111.4 | J349: 110.5 | K349: 111 | L349: 110 | M349: 111.5 | N349: 112 | O349: 111.8 | P349: 113.2 | Q349: 115.5 | R349: 118.5 | S349: 119.7 | T349: 122.9 | U349: 123.4 | V349: 126.1 | W349: 126.7 | X349: 121.7 | Y349: 119.6 | Z349: 119.5 | AA349: 120.5 | AB349: 121.3 | AC349: 123.2 | AD349: 125.2 | AE349: 129.4 | AF349: 130.9 | AG349: 129 | AH349: 127.9 | AI349: 127.3 | AJ349: 124.7 | AK349: 124.3 | AL349: 123.4 | AM349: 122.8 | AN349: 124.1 | AO349: 124.8 | AP349: 126 | AQ349: 126.1 | AR349: 127.6 | AS349: 127.9 | AT349: 129.3 | AU349: 129.6 | AV349: 129.2 | AW349: 128.4 | AX349: 126.8 | AY349: 127.3 | AZ349: 131.1 | BA349: 133.6 | BB349: 136.1 | BC349: 137 | BD349: 136 | BE349: 135.9 | BF349: 136.2 | BG349: 136.5 | BH349: 133.9 | BI349: 133.3 | BJ349: 133.4 | BK349: 133.7 | BL349: 134.3 | BM349: 133.8 | BN349: 134.7 | BO349: 140 | BP349: 142.1 | BQ349: 138.7 | BR349: 140.6 | BS349: 142.5 | BT349: 137.8 | BU349: 135.6 | BV349: 133.7 | BW349: 133.7 | BX349: 135.4 | BY349: 135.4 | BZ349: 136.8 | CA349: 138.9 | CB349: 139.1 | CC349: 138.9 | CD349: 139.9 | CE349: 139.7 | CF349: 137.6 | CG349: 138.3 | CH349: 138.1 | CI349: 138.5 | CJ349: 141.5 | CK349: 142.8 | CL349: 144.2 | CM349: 145.7 | CN349: 147.3 | CO349: 147.4 | CP349: 150.6 | CQ349: 152.4 | CR349: 153 | CS349: 152.2 | CT349: 148.1 | CU349: 145.7 | CV349: 147.7 | CW349: 146.7 | CX349: 148.7 | CY349: 152.5 | CZ349: 154.3 | DA349: 158 | DB349: 159.9 | DC349: 159.7 | DD349: 154.7 | DE349: 151.8 | DF349: 153.4 | DG349: 153.9 | DH349: 158.8 | DI349: 158.8 | DJ349: 158.7 | DK349: 159.4 | DL349: 160.1 | DM349: 162.1 | DN349: 166.7 | DO349: 170.6 | DP349: 169.2 | DQ349: 166.3 | DR349: 166.7 | DS349: 168.2 | DT349: 173.3 | DU349: 175.6 | DV349: 177.4 | DW349: 174.2 | DX349: 176.2 | DY349: 175.1 | DZ349: 177.7 | EA349: 174.9 | EB349: 170.7 | EC349: 171.5 | ED349: 171.3 | EE349: 172.1 | EF349: 174 | EG349: 172.9 | EH349: 175.1 | EI349: 188.7 | EJ349: 187.1 | EK349: 178.4 | EL349: 180.3
A350: a. FOOD GRAINS (CEREALS+PULSES) | B350: 1101010000 | C350: 3.46238 | D350: 104.8 | E350: 106 | F350: 107.4 | G350: 111.5 | H350: 117.4 | I350: 119.4 | J350: 118.4 | K350: 119.3 | L350: 119.1 | M350: 119.2 | N350: 119.6 | O350: 119.6 | P350: 119.9 | Q350: 120 | R350: 122.2 | S350: 124 | T350: 124.8 | U350: 125.4 | V350: 125.5 | W350: 126.3 | X350: 126.2 | Y350: 126.3 | Z350: 126.4 | AA350: 126.8 | AB350: 126.3 | AC350: 126.7 | AD350: 126.8 | AE350: 129 | AF350: 129.8 | AG350: 129.4 | AH350: 129.1 | AI350: 128.5 | AJ350: 127.9 | AK350: 129.1 | AL350: 129.4 | AM350: 129 | AN350: 129.5 | AO350: 131.7 | AP350: 132.9 | AQ350: 133.7 | AR350: 135.3 | AS350: 137 | AT350: 140.3 | AU350: 141.2 | AV350: 141.8 | AW350: 142.3 | AX350: 141.2 | AY350: 140.8 | AZ350: 143.5 | BA350: 147 | BB350: 150.6 | BC350: 154.8 | BD350: 153.6 | BE350: 153 | BF350: 155.2 | BG350: 158.2 | BH350: 157.5 | BI350: 153 | BJ350: 150.2 | BK350: 146.8 | BL350: 146.6 | BM350: 144.8 | BN350: 143.5 | BO350: 143.2 | BP350: 143 | BQ350: 144 | BR350: 143.1 | BS350: 141.7 | BT350: 140.6 | BU350: 140.4 | BV350: 139.9 | BW350: 140.5 | BX350: 140.4 | BY350: 140.8 | BZ350: 141 | CA350: 142.6 | CB350: 145.1 | CC350: 145.4 | CD350: 146.7 | CE350: 148.6 | CF350: 150.4 | CG350: 151.8 | CH350: 153.8 | CI350: 153.4 | CJ350: 153.5 | CK350: 154.3 | CL350: 155.4 | CM350: 157.5 | CN350: 159.2 | CO350: 160.1 | CP350: 160.8 | CQ350: 162.5 | CR350: 163.5 | CS350: 165 | CT350: 163.4 | CU350: 159.8 | CV350: 161.8 | CW350: 162.1 | CX350: 161.6 | CY350: 161.1 | CZ350: 159.7 | DA350: 158.6 | DB350: 158.1 | DC350: 158.8 | DD350: 157.4 | DE350: 157.2 | DF350: 157.4 | DG350: 158.1 | DH350: 161 | DI350: 162.2 | DJ350: 161.3 | DK350: 159.7 | DL350: 161.1 | DM350: 163 | DN350: 163.7 | DO350: 164.7 | DP350: 165.1 | DQ350: 165.5 | DR350: 165.9 | DS350: 169.1 | DT350: 171.2 | DU350: 171.7 | DV350: 170.7 | DW350: 172.6 | DX350: 177 | DY350: 178.4 | DZ350: 179.6 | EA350: 181.9 | EB350: 184.4 | EC350: 187 | ED350: 185.4 | EE350: 183 | EF350: 183.7 | EG350: 183.2 | EH350: 185.2 | EI350: 187.3 | EJ350: 190.1 | EK350: 194.2 | EL350: 197.4
A351: Paddy | B351: 1101010101 | C351: 1.43052 | D351: 104.2 | E351: 104.2 | F351: 107 | G351: 111 | H351: 114 | I351: 116.1 | J351: 116.6 | K351: 116.3 | L351: 115.9 | M351: 116.7 | N351: 117.9 | O351: 118.7 | P351: 120.4 | Q351: 121.9 | R351: 124.9 | S351: 129.4 | T351: 132 | U351: 131.3 | V351: 131 | W351: 131.3 | X351: 130.6 | Y351: 131.1 | Z351: 132.3 | AA351: 132.6 | AB351: 133.7 | AC351: 136 | AD351: 137.2 | AE351: 139.6 | AF351: 140.5 | AG351: 140.5 | AH351: 140 | AI351: 138 | AJ351: 134.6 | AK351: 133.5 | AL351: 134.1 | AM351: 132 | AN351: 132.6 | AO351: 134.2 | AP351: 133.6 | AQ351: 133.4 | AR351: 133.9 | AS351: 135.2 | AT351: 135.8 | AU351: 135.6 | AV351: 135.4 | AW351: 135.8 | AX351: 135.3 | AY351: 135.2 | AZ351: 136.3 | BA351: 139.1 | BB351: 142.2 | BC351: 144.2 | BD351: 144.6 | BE351: 144.7 | BF351: 145.1 | BG351: 145 | BH351: 144.2 | BI351: 143.8 | BJ351: 146.4 | BK351: 147.7 | BL351: 147.6 | BM351: 148 | BN351: 148.4 | BO351: 149.1 | BP351: 148.5 | BQ351: 148.8 | BR351: 149.6 | BS351: 149.2 | BT351: 148.8 | BU351: 150.4 | BV351: 151.4 | BW351: 152.6 | BX351: 153.3 | BY351: 154.2 | BZ351: 153.9 | CA351: 155 | CB351: 155.6 | CC351: 155.7 | CD351: 155.7 | CE351: 155.5 | CF351: 155.7 | CG351: 155.8 | CH351: 156.5 | CI351: 156.6 | CJ351: 157 | CK351: 157.6 | CL351: 158.4 | CM351: 159.9 | CN351: 160.8 | CO351: 161.9 | CP351: 162.7 | CQ351: 162.1 | CR351: 162 | CS351: 162.3 | CT351: 162.3 | CU351: 159.3 | CV351: 162.7 | CW351: 163.1 | CX351: 165.6 | CY351: 165.8 | CZ351: 165.4 | DA351: 165 | DB351: 163.7 | DC351: 163.1 | DD351: 162.2 | DE351: 162 | DF351: 161.7 | DG351: 161.5 | DH351: 162 | DI351: 162.2 | DJ351: 161.7 | DK351: 161.2 | DL351: 161.8 | DM351: 162.3 | DN351: 162.8 | DO351: 162.8 | DP351: 162.6 | DQ351: 162.9 | DR351: 161.7 | DS351: 163.1 | DT351: 164.4 | DU351: 165.1 | DV351: 165.5 | DW351: 166.2 | DX351: 168.8 | DY351: 171.7 | DZ351: 173.6 | EA351: 173.3 | EB351: 173.7 | EC351: 174.6 | ED351: 175.6 | EE351: 175.4 | EF351: 176.2 | EG351: 177.2 | EH351: 178.2 | EI351: 181.2 | EJ351: 184.3 | EK351: 187 | EL351: 190.2
A352: Barley | B352: 1101010106 | C352: 0.01437 | D352: 117.1 | E352: 118 | F352: 111.2 | G352: 113.2 | H352: 113.8 | I352: 111.8 | J352: 110.5 | K352: 113.9 | L352: 119 | M352: 119.4 | N352: 120.2 | O352: 119.5 | P352: 116.5 | Q352: 114.7 | R352: 115.8 | S352: 115.8 | T352: 116.3 | U352: 118 | V352: 118.6 | W352: 120.1 | X352: 123.3 | Y352: 123.9 | Z352: 123.5 | AA352: 124.1 | AB352: 119.2 | AC352: 120.7 | AD352: 118.2 | AE352: 120.1 | AF352: 124.2 | AG352: 127.1 | AH352: 129.8 | AI352: 128.4 | AJ352: 131 | AK352: 135.4 | AL352: 134.7 | AM352: 132.6 | AN352: 120.1 | AO352: 122.7 | AP352: 120.7 | AQ352: 121.9 | AR352: 122.6 | AS352: 124.3 | AT352: 128.5 | AU352: 133.1 | AV352: 136.1 | AW352: 138.5 | AX352: 141.6 | AY352: 139.4 | AZ352: 143.4 | BA352: 148.7 | BB352: 151.8 | BC352: 154.2 | BD352: 155.5 | BE352: 154 | BF352: 153.6 | BG352: 159.5 | BH352: 161.2 | BI352: 161.6 | BJ352: 161.9 | BK352: 156.9 | BL352: 144.5 | BM352: 137.7 | BN352: 138.1 | BO352: 139.3 | BP352: 139.1 | BQ352: 140.3 | BR352: 141.2 | BS352: 140.4 | BT352: 142.9 | BU352: 141.6 | BV352: 141 | BW352: 140.8 | BX352: 138.9 | BY352: 139.8 | BZ352: 141.7 | CA352: 141 | CB352: 145 | CC352: 146.7 | CD352: 150.2 | CE352: 153.5 | CF352: 154.8 | CG352: 159.2 | CH352: 163.4 | CI352: 163.9 | CJ352: 159 | CK352: 160.9 | CL352: 167 | CM352: 169 | CN352: 173.4 | CO352: 175.4 | CP352: 174.4 | CQ352: 174.9 | CR352: 176.8 | CS352: 180.4 | CT352: 181.7 | CU352: 182.3 | CV352: 177.8 | CW352: 166.3 | CX352: 157.4 | CY352: 153.1 | CZ352: 150.3 | DA352: 149.1 | DB352: 148.6 | DC352: 149.4 | DD352: 152 | DE352: 151.6 | DF352: 149.1 | DG352: 150 | DH352: 150 | DI352: 154.6 | DJ352: 156 | DK352: 156.7 | DL352: 160 | DM352: 166.4 | DN352: 170.7 | DO352: 174.8 | DP352: 179.9 | DQ352: 183.6 | DR352: 188.4 | DS352: 187 | DT352: 219.3 | DU352: 233.4 | DV352: 234.9 | DW352: 235 | DX352: 234 | DY352: 234.4 | DZ352: 231.8 | EA352: 238.6 | EB352: 243 | EC352: 239.7 | ED352: 238.9 | EE352: 218.6 | EF352: 202.8 | EG352: 187.8 | EH352: 191.6 | EI352: 190.6 | EJ352: 191.1 | EK352: 195.5 | EL352: 202.3
A353: Tapioca | B353: 1101020104 | C353: 0.07213 | D353: 87.5 | E353: 89.2 | F353: 87 | G353: 83.6 | H353: 80.3 | I353: 93.7 | J353: 101.9 | K353: 94.7 | L353: 101.9 | M353: 116.8 | N353: 143.7 | O353: 157.1 | P353: 162.6 | Q353: 155.1 | R353: 146.6 | S353: 150.3 | T353: 175.9 | U353: 188.6 | V353: 198.2 | W353: 196.2 | X353: 209.9 | Y353: 216 | Z353: 220.4 | AA353: 199.1 | AB353: 191.6 | AC353: 171.3 | AD353: 151.4 | AE353: 140.1 | AF353: 134.3 | AG353: 129.9 | AH353: 129.4 | AI353: 126.5 | AJ353: 123.4 | AK353: 111.3 | AL353: 107.6 | AM353: 114.6 | AN353: 115.2 | AO353: 114 | AP353: 112.1 | AQ353: 108.5 | AR353: 104.8 | AS353: 109.2 | AT353: 110.7 | AU353: 107.5 | AV353: 106.6 | AW353: 103.2 | AX353: 107.1 | AY353: 110.4 | AZ353: 124.1 | BA353: 130.2 | BB353: 132.2 | BC353: 140.9 | BD353: 171.7 | BE353: 181.6 | BF353: 186.8 | BG353: 194.6 | BH353: 199 | BI353: 196.7 | BJ353: 197.5 | BK353: 207.8 | BL353: 205.1 | BM353: 206.7 | BN353: 197.4 | BO353: 199.4 | BP353: 194.7 | BQ353: 185.9 | BR353: 177.6 | BS353: 163.4 | BT353: 156.1 | BU353: 147.1 | BV353: 141.5 | BW353: 148.8 | BX353: 151.5 | BY353: 135.8 | BZ353: 124.8 | CA353: 123.4 | CB353: 123.2 | CC353: 131.5 | CD353: 133.5 | CE353: 132.4 | CF353: 137.9 | CG353: 144.3 | CH353: 140.2 | CI353: 145.6 | CJ353: 152.4 | CK353: 155.5 | CL353: 156.5 | CM353: 155.2 | CN353: 155.7 | CO353: 156.5 | CP353: 153 | CQ353: 166.5 | CR353: 175.4 | CS353: 181.2 | CT353: 186.1 | CU353: 188.6 | CV353: 198.9 | CW353: 188.6 | CX353: 179.4 | CY353: 166.1 | CZ353: 162.8 | DA353: 163 | DB353: 163.3 | DC353: 156.2 | DD353: 150 | DE353: 152.8 | DF353: 154.3 | DG353: 151.4 | DH353: 154.4 | DI353: 154.3 | DJ353: 149.9 | DK353: 149.3 | DL353: 146.8 | DM353: 143.5 | DN353: 142.5 | DO353: 151.9 | DP353: 168.9 | DQ353: 180.7 | DR353: 181.1 | DS353: 196.3 | DT353: 211.1 | DU353: 214.5 | DV353: 223 | DW353: 242.5 | DX353: 255.9 | DY353: 265.7 | DZ353: 285.6 | EA353: 277.3 | EB353: 255.6 | EC353: 256.9 | ED353: 247.9 | EE353: 252.2 | EF353: 262.5 | EG353: 253.8 | EH353: 244 | EI353: 230.2 | EJ353: 230.7 | EK353: 234.5 | EL353: 233
A354: Radish | B354: 1101020113 | C354: 0.03942 | D354: 107.7 | E354: 103.7 | F354: 118.7 | G354: 163.6 | H354: 145.2 | I354: 151.6 | J354: 142.4 | K354: 99.9 | L354: 75.6 | M354: 89.4 | N354: 88.2 | O354: 93.2 | P354: 103.3 | Q354: 101.6 | R354: 132.3 | S354: 165 | T354: 259.8 | U354: 229.1 | V354: 204.4 | W354: 118.9 | X354: 101 | Y354: 81.8 | Z354: 95.5 | AA354: 78.6 | AB354: 91.9 | AC354: 94.6 | AD354: 111.2 | AE354: 128.6 | AF354: 179.2 | AG354: 188.1 | AH354: 156.2 | AI354: 111.7 | AJ354: 97.5 | AK354: 80.3 | AL354: 67.6 | AM354: 105.1 | AN354: 98.5 | AO354: 86.7 | AP354: 84.1 | AQ354: 121.9 | AR354: 121.9 | AS354: 121.9 | AT354: 121.9 | AU354: 121.9 | AV354: 121.9 | AW354: 121.9 | AX354: 121.9 | AY354: 121.9 | AZ354: 131.5 | BA354: 126.7 | BB354: 139.5 | BC354: 152.6 | BD354: 158.8 | BE354: 153.7 | BF354: 160.2 | BG354: 145.2 | BH354: 104 | BI354: 102.9 | BJ354: 100.7 | BK354: 109 | BL354: 121.3 | BM354: 119.5 | BN354: 116.5 | BO354: 121.3 | BP354: 133.8 | BQ354: 124.1 | BR354: 123.9 | BS354: 110.1 | BT354: 105.9 | BU354: 105.6 | BV354: 103.4 | BW354: 102.4 | BX354: 100.7 | BY354: 98.5 | BZ354: 96.6 | CA354: 105.5 | CB354: 107.7 | CC354: 124 | CD354: 112.4 | CE354: 94.8 | CF354: 92.7 | CG354: 92 | CH354: 97.6 | CI354: 121.6 | CJ354: 135.5 | CK354: 154.7 | CL354: 166.7 | CM354: 164.3 | CN354: 151.8 | CO354: 158.3 | CP354: 157.1 | CQ354: 124.8 | CR354: 109.9 | CS354: 96.4 | CT354: 104.3 | CU354: 114.1 | CV354: 121.2 | CW354: 135.6 | CX354: 152.8 | CY354: 169.3 | CZ354: 188.2 | DA354: 231.5 | DB354: 213.5 | DC354: 122.9 | DD354: 87.9 | DE354: 78.7 | DF354: 90.8 | DG354: 102.2 | DH354: 117.1 | DI354: 135 | DJ354: 146.8 | DK354: 173.1 | DL354: 175.7 | DM354: 173.6 | DN354: 214.4 | DO354: 220.9 | DP354: 195.6 | DQ354: 166.1 | DR354: 179.3 | DS354: 180.3 | DT354: 208.1 | DU354: 234.7 | DV354: 258.8 | DW354: 260.5 | DX354: 262.1 | DY354: 226.9 | DZ354: 215.4 | EA354: 221 | EB354: 151.9 | EC354: 117 | ED354: 121.8 | EE354: 149 | EF354: 171.6 | EG354: 208.7 | EH354: 189.3 | EI354: 197.6 | EJ354: 239.7 | EK354: 237.5 | EL354: 224.1
A355: Cucumber | B355: 1101020114 | C355: 0.00906 | D355: 134.7 | E355: 74.7 | F355: 95.9 | G355: 105.8 | H355: 104.5 | I355: 87.5 | J355: 85.9 | K355: 102 | L355: 123.8 | M355: 116.6 | N355: 119.6 | O355: 149.5 | P355: 132.5 | Q355: 114.8 | R355: 97.7 | S355: 115.5 | T355: 110.2 | U355: 113 | V355: 107.2 | W355: 117.7 | X355: 136.4 | Y355: 156.9 | Z355: 136.5 | AA355: 137.6 | AB355: 121.8 | AC355: 89.7 | AD355: 119 | AE355: 97.1 | AF355: 86.2 | AG355: 86.6 | AH355: 102.7 | AI355: 106.4 | AJ355: 112 | AK355: 156.5 | AL355: 164.3 | AM355: 120.7 | AN355: 109 | AO355: 112.6 | AP355: 121.2 | AQ355: 120.7 | AR355: 120.7 | AS355: 120.7 | AT355: 120.7 | AU355: 120.7 | AV355: 120.7 | AW355: 120.7 | AX355: 120.7 | AY355: 120.7 | AZ355: 154.8 | BA355: 144.5 | BB355: 159.5 | BC355: 116.9 | BD355: 104.4 | BE355: 106.6 | BF355: 114.5 | BG355: 142.4 | BH355: 148.6 | BI355: 129.5 | BJ355: 127.3 | BK355: 134.7 | BL355: 134.4 | BM355: 115.9 | BN355: 126.8 | BO355: 186.3 | BP355: 146.4 | BQ355: 124.9 | BR355: 123.1 | BS355: 136.1 | BT355: 121.8 | BU355: 123.6 | BV355: 131.3 | BW355: 115.3 | BX355: 117.9 | BY355: 121.4 | BZ355: 133.3 | CA355: 155.2 | CB355: 156.2 | CC355: 146.2 | CD355: 142.4 | CE355: 143 | CF355: 146.4 | CG355: 164.4 | CH355: 180 | CI355: 170.9 | CJ355: 143.6 | CK355: 136.6 | CL355: 151.7 | CM355: 185.4 | CN355: 202.6 | CO355: 193.7 | CP355: 184.1 | CQ355: 182.5 | CR355: 181 | CS355: 189.3 | CT355: 145.3 | CU355: 134.6 | CV355: 146.1 | CW355: 157 | CX355: 171.1 | CY355: 169.1 | CZ355: 152.7 | DA355: 193.2 | DB355: 193 | DC355: 145.1 | DD355: 127.5 | DE355: 159 | DF355: 170.2 | DG355: 180.6 | DH355: 169 | DI355: 151.1 | DJ355: 165.1 | DK355: 167.1 | DL355: 130.9 | DM355: 131.8 | DN355: 163.6 | DO355: 205.5 | DP355: 218.3 | DQ355: 181.1 | DR355: 179.8 | DS355: 154.6 | DT355: 163.5 | DU355: 138.8 | DV355: 165.5 | DW355: 167.2 | DX355: 174.5 | DY355: 172 | DZ355: 162.7 | EA355: 158.2 | EB355: 170.9 | EC355: 182.8 | ED355: 169.4 | EE355: 158.8 | EF355: 124.2 | EG355: 128.9 | EH355: 152.8 | EI355: 206.6 | EJ355: 155 | EK355: 149.1 | EL355: 168.2
A356: Pumpkin | B356: 1101020119 | C356: 0.00465 | D356: 133.6 | E356: 107.6 | F356: 103.3 | G356: 144.7 | H356: 128.5 | I356: 118.8 | J356: 103.2 | K356: 94.6 | L356: 111 | M356: 133.5 | N356: 142.7 | O356: 164.2 | P356: 146.2 | Q356: 113.4 | R356: 118.9 | S356: 152.3 | T356: 166.5 | U356: 180.7 | V356: 224.3 | W356: 211.3 | X356: 136.7 | Y356: 169.8 | Z356: 143.5 | AA356: 145.1 | AB356: 119.6 | AC356: 88.3 | AD356: 116.3 | AE356: 142.5 | AF356: 148.1 | AG356: 173.8 | AH356: 159.9 | AI356: 182 | AJ356: 145 | AK356: 167.9 | AL356: 162.6 | AM356: 187.9 | AN356: 135.9 | AO356: 115.3 | AP356: 104.2 | AQ356: 118.5 | AR356: 118.5 | AS356: 118.5 | AT356: 118.5 | AU356: 118.5 | AV356: 118.5 | AW356: 118.5 | AX356: 118.5 | AY356: 118.5 | AZ356: 153.3 | BA356: 134.2 | BB356: 130.8 | BC356: 165.5 | BD356: 161.1 | BE356: 150.9 | BF356: 126.2 | BG356: 133 | BH356: 128 | BI356: 126.9 | BJ356: 132.4 | BK356: 141.1 | BL356: 143.1 | BM356: 131.9 | BN356: 122.1 | BO356: 140.7 | BP356: 155 | BQ356: 143.8 | BR356: 137.1 | BS356: 145.4 | BT356: 148.8 | BU356: 154.5 | BV356: 144.6 | BW356: 134.4 | BX356: 112.9 | BY356: 119.4 | BZ356: 116.7 | CA356: 122.7 | CB356: 144.8 | CC356: 121 | CD356: 122.6 | CE356: 126.8 | CF356: 125.8 | CG356: 123.9 | CH356: 127.3 | CI356: 151.7 | CJ356: 165 | CK356: 174.3 | CL356: 156.1 | CM356: 151.8 | CN356: 134.3 | CO356: 139.5 | CP356: 154.1 | CQ356: 165.3 | CR356: 196.1 | CS356: 190.5 | CT356: 176.1 | CU356: 167 | CV356: 172.3 | CW356: 150.4 | CX356: 157.6 | CY356: 166.5 | CZ356: 170.4 | DA356: 175.9 | DB356: 190.2 | DC356: 169.8 | DD356: 177.1 | DE356: 153.6 | DF356: 163 | DG356: 158.3 | DH356: 151.2 | DI356: 145.7 | DJ356: 147.9 | DK356: 177.7 | DL356: 167 | DM356: 131.4 | DN356: 129.8 | DO356: 144.2 | DP356: 160.1 | DQ356: 189.9 | DR356: 204.7 | DS356: 190.2 | DT356: 158.8 | DU356: 146.6 | DV356: 146.7 | DW356: 185.9 | DX356: 212.6 | DY356: 212.2 | DZ356: 209.6 | EA356: 194.4 | EB356: 170.8 | EC356: 150.8 | ED356: 159.2 | EE356: 170.1 | EF356: 156 | EG356: 130.8 | EH356: 135.9 | EI356: 170.2 | EJ356: 169.5 | EK356: 154.8 | EL356: 160.7
A357: Jackfruit | B357: 1101020217 | C357: 0.02458 | D357: 113.8 | E357: 104 | F357: 96.5 | G357: 102.3 | H357: 108.4 | I357: 139.7 | J357: 140.8 | K357: 141.5 | L357: 164.8 | M357: 269.7 | N357: 188.9 | O357: 130.8 | P357: 119.8 | Q357: 112.4 | R357: 107.8 | S357: 118.1 | T357: 114.5 | U357: 114.5 | V357: 114.5 | W357: 113.9 | X357: 128.4 | Y357: 140.4 | Z357: 153.4 | AA357: 147.1 | AB357: 128.3 | AC357: 103.6 | AD357: 102.1 | AE357: 106.5 | AF357: 118 | AG357: 118 | AH357: 118 | AI357: 131.1 | AJ357: 131.1 | AK357: 184 | AL357: 174.4 | AM357: 159.1 | AN357: 144.9 | AO357: 119.6 | AP357: 117.4 | AQ357: 107.8 | AR357: 107.8 | AS357: 107.8 | AT357: 107.8 | AU357: 107.8 | AV357: 107.8 | AW357: 107.8 | AX357: 107.8 | AY357: 107.8 | AZ357: 137.3 | BA357: 134.8 | BB357: 130.9 | BC357: 155.9 | BD357: 198.4 | BE357: 198.4 | BF357: 198.4 | BG357: 198.4 | BH357: 225.3 | BI357: 208.3 | BJ357: 193.8 | BK357: 198 | BL357: 185.2 | BM357: 179.6 | BN357: 174.1 | BO357: 185.5 | BP357: 194.4 | BQ357: 195.7 | BR357: 198.4 | BS357: 241.2 | BT357: 235.4 | BU357: 236.4 | BV357: 234.7 | BW357: 228.8 | BX357: 191.3 | BY357: 164.9 | BZ357: 116.6 | CA357: 99.2 | CB357: 102.3 | CC357: 109.8 | CD357: 118.9 | CE357: 129.5 | CF357: 140.5 | CG357: 136.9 | CH357: 124 | CI357: 121.7 | CJ357: 112.8 | CK357: 103.8 | CL357: 102.5 | CM357: 102.7 | CN357: 101.7 | CO357: 104.3 | CP357: 106.9 | CQ357: 110 | CR357: 121.3 | CS357: 139 | CT357: 117.6 | CU357: 131.6 | CV357: 135 | CW357: 124.2 | CX357: 131 | CY357: 145.9 | CZ357: 151.3 | DA357: 152.3 | DB357: 167.5 | DC357: 167.9 | DD357: 170.9 | DE357: 158.5 | DF357: 150.7 | DG357: 142.5 | DH357: 130 | DI357: 120.6 | DJ357: 113.6 | DK357: 105.6 | DL357: 109.6 | DM357: 112.2 | DN357: 121 | DO357: 137.8 | DP357: 136.6 | DQ357: 136.5 | DR357: 137.3 | DS357: 150.6 | DT357: 138.8 | DU357: 110.6 | DV357: 102.9 | DW357: 109.3 | DX357: 133 | DY357: 136.3 | DZ357: 140.6 | EA357: 147.5 | EB357: 143.4 | EC357: 139.4 | ED357: 137.7 | EE357: 139.4 | EF357: 131.5 | EG357: 116.6 | EH357: 110.5 | EI357: 101.2 | EJ357: 101.9 | EK357: 104 | EL357: 110.2
A358: Milk | B358: 1101030001 | C358: 4.43999 | D358: 105.1 | E358: 105.4 | F358: 106.2 | G358: 107.2 | H358: 106.7 | I358: 107.5 | J358: 108.3 | K358: 108.5 | L358: 108 | M358: 108.7 | N358: 109.8 | O358: 109.8 | P358: 110.3 | Q358: 111.8 | R358: 112.6 | S358: 113.5 | T358: 114.4 | U358: 115.4 | V358: 116.6 | W358: 117.4 | X358: 118.6 | Y358: 118.6 | Z358: 120.9 | AA358: 121.6 | AB358: 120.9 | AC358: 123.4 | AD358: 124.8 | AE358: 125.2 | AF358: 126.5 | AG358: 126.6 | AH358: 127 | AI358: 128.5 | AJ358: 129 | AK358: 129.2 | AL358: 129.1 | AM358: 129.2 | AN358: 129.7 | AO358: 130.2 | AP358: 130.4 | AQ358: 130.3 | AR358: 130.3 | AS358: 130.3 | AT358: 130.3 | AU358: 130.3 | AV358: 130.4 | AW358: 131.1 | AX358: 131.3 | AY358: 131.7 | AZ358: 131.9 | BA358: 132.1 | BB358: 133.4 | BC358: 134.2 | BD358: 134.4 | BE358: 134.6 | BF358: 134.8 | BG358: 134.7 | BH358: 135 | BI358: 135 | BJ358: 135.4 | BK358: 136.5 | BL358: 137.7 | BM358: 138.5 | BN358: 139.2 | BO358: 139.2 | BP358: 139.7 | BQ358: 140.4 | BR358: 140.2 | BS358: 140.2 | BT358: 140.2 | BU358: 140.3 | BV358: 140.6 | BW358: 140.7 | BX358: 141.2 | BY358: 141.8 | BZ358: 142.5 | CA358: 143.2 | CB358: 143.7 | CC358: 143.5 | CD358: 144.1 | CE358: 144.1 | CF358: 143.7 | CG358: 143.4 | CH358: 142.9 | CI358: 143.2 | CJ358: 143.2 | CK358: 143.4 | CL358: 145.5 | CM358: 145.3 | CN358: 145.9 | CO358: 145.7 | CP358: 146.2 | CQ358: 146.6 | CR358: 148.5 | CS358: 149 | CT358: 149.6 | CU358: 151.2 | CV358: 151.6 | CW358: 151.4 | CX358: 151.9 | CY358: 152.1 | CZ358: 152.3 | DA358: 153.8 | DB358: 154.6 | DC358: 154.7 | DD358: 154.1 | DE358: 154 | DF358: 154.9 | DG358: 155.2 | DH358: 154.7 | DI358: 154.9 | DJ358: 154.4 | DK358: 155.9 | DL358: 157 | DM358: 156.8 | DN358: 157.3 | DO358: 157.5 | DP358: 157.3 | DQ358: 157.4 | DR358: 157.8 | DS358: 161.6 | DT358: 163.3 | DU358: 163.9 | DV358: 164.2 | DW358: 164.4 | DX358: 165.5 | DY358: 165.5 | DZ358: 166.7 | EA358: 167.3 | EB358: 169.9 | EC358: 172.9 | ED358: 174.1 | EE358: 175.3 | EF358: 176.7 | EG358: 177.3 | EH358: 178.3 | EI358: 177.9 | EJ358: 179.6 | EK358: 180 | EL358: 180.2
A359: Fish-Marine | B359: 1101040003 | C359: 0.42182 | D359: 112.9 | E359: 113.9 | F359: 115.3 | G359: 116.7 | H359: 116.4 | I359: 116.4 | J359: 109.9 | K359: 116.9 | L359: 112.8 | M359: 112.5 | N359: 115.6 | O359: 115.9 | P359: 118.6 | Q359: 119.3 | R359: 117.5 | S359: 120.7 | T359: 120.8 | U359: 120.4 | V359: 118.9 | W359: 122.2 | X359: 121.8 | Y359: 123.1 | Z359: 122.6 | AA359: 119.5 | AB359: 122.3 | AC359: 125.7 | AD359: 128.1 | AE359: 128.9 | AF359: 127.4 | AG359: 121.2 | AH359: 122.1 | AI359: 122 | AJ359: 125.3 | AK359: 127.7 | AL359: 128.6 | AM359: 128.9 | AN359: 130.1 | AO359: 133.6 | AP359: 133.2 | AQ359: 135.1 | AR359: 132.2 | AS359: 126.3 | AT359: 124.3 | AU359: 125.2 | AV359: 128.8 | AW359: 131.2 | AX359: 132.9 | AY359: 133.7 | AZ359: 132.2 | BA359: 121.2 | BB359: 118.9 | BC359: 117.9 | BD359: 113.7 | BE359: 112.9 | BF359: 112.8 | BG359: 112.9 | BH359: 114.7 | BI359: 119.8 | BJ359: 119.3 | BK359: 118.8 | BL359: 118.9 | BM359: 118.4 | BN359: 124 | BO359: 123.5 | BP359: 122.7 | BQ359: 122.2 | BR359: 121.9 | BS359: 123.5 | BT359: 123.2 | BU359: 124.6 | BV359: 121.7 | BW359: 123.9 | BX359: 128.6 | BY359: 138.8 | BZ359: 143 | CA359: 143.2 | CB359: 137.9 | CC359: 126.2 | CD359: 124.1 | CE359: 125.6 | CF359: 129.7 | CG359: 138 | CH359: 140.8 | CI359: 133.1 | CJ359: 139.7 | CK359: 142.6 | CL359: 150.4 | CM359: 143 | CN359: 144.9 | CO359: 141.5 | CP359: 141.6 | CQ359: 150.3 | CR359: 147.4 | CS359: 161.4 | CT359: 163.3 | CU359: 153.6 | CV359: 148.8 | CW359: 146.1 | CX359: 148.7 | CY359: 147.1 | CZ359: 152.8 | DA359: 150.6 | DB359: 147.2 | DC359: 147.6 | DD359: 148.5 | DE359: 145.6 | DF359: 155.6 | DG359: 145.6 | DH359: 159.8 | DI359: 172.3 | DJ359: 174.1 | DK359: 162.6 | DL359: 164 | DM359: 164.2 | DN359: 149.6 | DO359: 153.4 | DP359: 146.9 | DQ359: 159.2 | DR359: 165.8 | DS359: 163.1 | DT359: 174.4 | DU359: 193.6 | DV359: 194.5 | DW359: 190.5 | DX359: 190.8 | DY359: 176.8 | DZ359: 161.2 | EA359: 163.7 | EB359: 161.3 | EC359: 171.5 | ED359: 180.1 | EE359: 179.2 | EF359: 183.4 | EG359: 195.7 | EH359: 199.5 | EI359: 193.1 | EJ359: 182.7 | EK359: 169.5 | EL359: 164.3
A360: Turmeric | B360: 1101050003 | C360: 0.10015 | D360: 66.8 | E360: 67.3 | F360: 65.9 | G360: 76 | H360: 84 | I360: 83.5 | J360: 81.2 | K360: 80 | L360: 82.2 | M360: 85.4 | N360: 89.3 | O360: 96.2 | P360: 104.2 | Q360: 107.6 | R360: 105.1 | S360: 104.5 | T360: 100.4 | U360: 99 | V360: 100 | W360: 101.4 | X360: 101.4 | Y360: 103 | Z360: 104.6 | AA360: 105.3 | AB360: 104.2 | AC360: 103.1 | AD360: 103.3 | AE360: 104.1 | AF360: 105.7 | AG360: 106.3 | AH360: 106.6 | AI360: 108.6 | AJ360: 113.6 | AK360: 116.1 | AL360: 120.7 | AM360: 119.7 | AN360: 119.7 | AO360: 119.3 | AP360: 117.9 | AQ360: 117.4 | AR360: 115.5 | AS360: 117 | AT360: 118.8 | AU360: 127.2 | AV360: 129 | AW360: 126.5 | AX360: 125.2 | AY360: 125 | AZ360: 124.5 | BA360: 121.8 | BB360: 120.5 | BC360: 121 | BD360: 118.9 | BE360: 115.8 | BF360: 115 | BG360: 116.4 | BH360: 115.7 | BI360: 113.8 | BJ360: 112.3 | BK360: 111.5 | BL360: 110.1 | BM360: 107 | BN360: 108 | BO360: 110.5 | BP360: 116.8 | BQ360: 122.6 | BR360: 129.3 | BS360: 128.7 | BT360: 128.3 | BU360: 125.5 | BV360: 125 | BW360: 124.7 | BX360: 122.4 | BY360: 124.6 | BZ360: 124.2 | CA360: 124.2 | CB360: 122.5 | CC360: 119.1 | CD360: 115.3 | CE360: 117.4 | CF360: 117.2 | CG360: 115.6 | CH360: 111.9 | CI360: 110.5 | CJ360: 111.5 | CK360: 114.7 | CL360: 115 | CM360: 113.4 | CN360: 116.5 | CO360: 118.3 | CP360: 114.9 | CQ360: 114.7 | CR360: 112.9 | CS360: 109.7 | CT360: 109.3 | CU360: 117 | CV360: 116.7 | CW360: 116.5 | CX360: 114.9 | CY360: 113.2 | CZ360: 115.4 | DA360: 113.5 | DB360: 111.5 | DC360: 112.2 | DD360: 113 | DE360: 113.7 | DF360: 118.6 | DG360: 126.3 | DH360: 132.6 | DI360: 128.5 | DJ360: 127.4 | DK360: 121.4 | DL360: 120.8 | DM360: 118.5 | DN360: 117.2 | DO360: 117.3 | DP360: 123.1 | DQ360: 127.1 | DR360: 127.2 | DS360: 126.6 | DT360: 120.7 | DU360: 119.7 | DV360: 118.3 | DW360: 117.9 | DX360: 115.2 | DY360: 114.9 | DZ360: 110.4 | EA360: 114 | EB360: 115.7 | EC360: 116.6 | ED360: 114.2 | EE360: 115 | EF360: 112.5 | EG360: 110.1 | EH360: 111 | EI360: 127.1 | EJ360: 156.6 | EK360: 163.1 | EL360: 163.8
A361: Cardamom | B361: 1101050004 | C361: 0.01434 | D361: 118.5 | E361: 119.3 | F361: 113.6 | G361: 112.1 | H361: 112.7 | I361: 105.2 | J361: 101.6 | K361: 101.8 | L361: 108.9 | M361: 109.6 | N361: 110.2 | O361: 102.3 | P361: 100.6 | Q361: 97.4 | R361: 97.2 | S361: 96.4 | T361: 100.8 | U361: 104.7 | V361: 104.2 | W361: 103 | X361: 103.2 | Y361: 103.6 | Z361: 105.7 | AA361: 108.5 | AB361: 113.6 | AC361: 118.8 | AD361: 115 | AE361: 113.8 | AF361: 113.5 | AG361: 121.3 | AH361: 119.9 | AI361: 119.1 | AJ361: 122.2 | AK361: 133 | AL361: 138.3 | AM361: 132.8 | AN361: 129.5 | AO361: 127 | AP361: 124.4 | AQ361: 124.1 | AR361: 122.3 | AS361: 121.4 | AT361: 120.6 | AU361: 119.9 | AV361: 120.3 | AW361: 122 | AX361: 119 | AY361: 116.9 | AZ361: 119.5 | BA361: 126.2 | BB361: 128.3 | BC361: 128 | BD361: 137.3 | BE361: 140.4 | BF361: 138.2 | BG361: 142 | BH361: 148.9 | BI361: 154.3 | BJ361: 157 | BK361: 151 | BL361: 143.8 | BM361: 134.4 | BN361: 128.4 | BO361: 130.8 | BP361: 136.6 | BQ361: 141.5 | BR361: 125.6 | BS361: 114.8 | BT361: 114.9 | BU361: 125.9 | BV361: 128.9 | BW361: 126.9 | BX361: 125.7 | BY361: 122.1 | BZ361: 120.8 | CA361: 123.4 | CB361: 126.5 | CC361: 134.7 | CD361: 130.6 | CE361: 131.7 | CF361: 132.2 | CG361: 134.3 | CH361: 138.5 | CI361: 134.9 | CJ361: 145.7 | CK361: 169 | CL361: 180.6 | CM361: 196.7 | CN361: 203.9 | CO361: 189.3 | CP361: 180.5 | CQ361: 178.5 | CR361: 185.5 | CS361: 207.7 | CT361: 197.6 | CU361: 179.9 | CV361: 178.2 | CW361: 174.1 | CX361: 158.2 | CY361: 157.2 | CZ361: 157.5 | DA361: 155 | DB361: 136.7 | DC361: 137.3 | DD361: 148.9 | DE361: 146.2 | DF361: 138.4 | DG361: 137.5 | DH361: 132.3 | DI361: 119.1 | DJ361: 120.9 | DK361: 120.7 | DL361: 125.3 | DM361: 127.9 | DN361: 128.7 | DO361: 134.6 | DP361: 130.4 | DQ361: 120.2 | DR361: 120 | DS361: 119.3 | DT361: 120.8 | DU361: 115.7 | DV361: 108.8 | DW361: 109.3 | DX361: 115.5 | DY361: 114.1 | DZ361: 113 | EA361: 108.1 | EB361: 106.5 | EC361: 109.2 | ED361: 131.9 | EE361: 153.9 | EF361: 156.4 | EG361: 154.2 | EH361: 144.2 | EI361: 153.8 | EJ361: 213.1 | EK361: 226.3 | EL361: 211.6
... A870: Non Mechanical Toys | B870: 1322040004 | C870: 0.00014 | D870: 107 | E870: 107 | F870: 107 | G870: 107 | H870: 107 | I870: 107 | J870: 107 | K870: 107 | L870: 107 | M870: 107.3 | N870: 107.3 | O870: 107.3 | P870: 113.2 | Q870: 113.2 | R870: 113.2 | S870: 113.2 | T870: 113.2 | U870: 113.2 | V870: 113.2 | W870: 113.2 | X870: 113.2 | Y870: 113.7 | Z870: 113.7 | AA870: 113.7 | AB870: 121 | AC870: 121 | AD870: 121 | AE870: 121 | AF870: 121 | AG870: 121.8 | AH870: 121.8 | AI870: 121.8 | AJ870: 121.8 | AK870: 122.4 | AL870: 122.4 | AM870: 122.4 | AN870: 128.5 | AO870: 128.5 | AP870: 128.5 | AQ870: 130.7 | AR870: 130.7 | AS870: 130.7 | AT870: 130.7 | AU870: 130.7 | AV870: 130.7 | AW870: 131.1 | AX870: 131.1 | AY870: 136.8 | AZ870: 137.4 | BA870: 137.4 | BB870: 137.4 | BC870: 137.4 | BD870: 137.4 | BE870: 137.4 | BF870: 137.4 | BG870: 137.4 | BH870: 137.4 | BI870: 137.8 | BJ870: 137.8 | BK870: 137.8 | BL870: 137.8 | BM870: 137.8 | BN870: 137.4 | BO870: 137.8 | BP870: 141.2 | BQ870: 140.4 | BR870: 140.4 | BS870: 140.4 | BT870: 140.4 | BU870: 140.8 | BV870: 141.6 | BW870: 141.6 | BX870: 145.4 | BY870: 141.6 | BZ870: 141.6 | CA870: 141.6 | CB870: 145.5 | CC870: 145.4 | CD870: 162.3 | CE870: 162.3 | CF870: 162.3 | CG870: 162.8 | CH870: 162.9 | CI870: 162.8 | CJ870: 166.8 | CK870: 169.5 | CL870: 172 | CM870: 172 | CN870: 176.5 | CO870: 178.6 | CP870: 194.2 | CQ870: 194.2 | CR870: 192.5 | CS870: 191.6 | CT870: 189.9 | CU870: 190.7 | CV870: 189.2 | CW870: 189.2 | CX870: 189 | CY870: 189 | CZ870: 188 | DA870: 188 | DB870: 186.2 | DC870: 187.3 | DD870: 192.7 | DE870: 192.7 | DF870: 192.7 | DG870: 192.7 | DH870: 192.7 | DI870: 192.7 | DJ870: 192.5 | DK870: 192.5 | DL870: 192.5 | DM870: 195.2 | DN870: 196 | DO870: 202.3 | DP870: 202.4 | DQ870: 202.6 | DR870: 202.9 | DS870: 202.9 | DT870: 203.7 | DU870: 203.8 | DV870: 211.5 | DW870: 211.5 | DX870: 207.4 | DY870: 207.4 | DZ870: 207.8 | EA870: 207.8 | EB870: 208.5 | EC870: 208.5 | ED870: 208.5 | EE870: 207 | EF870: 207 | EG870: 207.8 | EH870: 207.8 | EI870: 208.5 | EJ870: 210 | EK870: 211.5 | EL870: 211.5

Sheet WPI_data_prepped
A1: COMM_NAME | B1: COMM_CODE | C1: COMM_WT | D1: BASE Price | E1: WT_INDX042012 | F1: WT_INDX052012 | G1: WT_INDX062012 | H1: WT_INDX072012 | I1: WT_INDX082012 | J1: WT_INDX092012 | K1: WT_INDX102012 | L1: WT_INDX112012 | M1: WT_INDX122012 | N1: WT_INDX012013 | O1: WT_INDX022013 | P1: WT_INDX032013 | Q1: WT_INDX042013 | R1: WT_INDX052013 | S1: WT_INDX062013 | T1: WT_INDX072013 | U1: WT_INDX082013 | V1: WT_INDX092013 | W1: WT_INDX102013 | X1: WT_INDX112013 | Y1: WT_INDX122013 | Z1: WT_INDX012014 | AA1: WT_INDX022014 | AB1: WT_INDX032014 | AC1: WT_INDX042014 | AD1: WT_INDX052014 | AE1: WT_INDX062014 | AF1: WT_INDX072014 | AG1: WT_INDX082014 | AH1: WT_INDX092014 | AI1: WT_INDX102014 | AJ1: WT_INDX112014 | AK1: WT_INDX122014 | AL1: WT_INDX012015 | AM1: WT_INDX022015 | AN1: WT_INDX032015 | AO1: WT_INDX042015 | AP1: WT_INDX052015 | AQ1: WT_INDX062015 | AR1: WT_INDX072015 | AS1: WT_INDX082015 | AT1: WT_INDX092015 | AU1: WT_INDX102015 | AV1: WT_INDX112015 | AW1: WT_INDX122015 | AX1: WT_INDX012016 | AY1: WT_INDX022016 | AZ1: WT_INDX032016 | BA1: WT_INDX042016 | BB1: WT_INDX052016 | BC1: WT_INDX062016 | BD1: WT_INDX072016 | BE1: WT_INDX082016 | BF1: WT_INDX092016 | BG1: WT_INDX102016 | BH1: WT_INDX112016 | BI1: WT_INDX122016 | BJ1: WT_INDX012017 | BK1: WT_INDX022017 | BL1: WT_INDX032017 | BM1: WT_INDX042017 | BN1: WT_INDX052017 | BO1: WT_INDX062017 | BP1: WT_INDX072017 | BQ1: WT_INDX082017 | BR1: WT_INDX092017 | BS1: WT_INDX102017 | BT1: WT_INDX112017 | BU1: WT_INDX122017 | BV1: WT_INDX012018 | BW1: WT_INDX022018 | BX1: WT_INDX032018 | BY1: WT_INDX042018 | BZ1: WT_INDX052018 | CA1: WT_INDX062018 | CB1: WT_INDX072018 | CC1: WT_INDX082018 | CD1: WT_INDX092018 | CE1: WT_INDX102018 | CF1: WT_INDX112018 | CG1: WT_INDX122018 | CH1: WT_INDX012019 | CI1: WT_INDX022019 | CJ1: WT_INDX032019 | CK1: WT_INDX042019 | CL1: WT_INDX052019 | CM1: WT_INDX062019 | CN1: WT_INDX072019 | CO1: WT_INDX082019 | CP1: WT_INDX092019 | CQ1: WT_INDX102019 | CR1: WT_INDX112019 | CS1: WT_INDX122019 | CT1: WT_INDX012020 | CU1: WT_INDX022020 | CV1: WT_INDX032020 | CW1: WT_INDX042020 | CX1: WT_INDX052020 | CY1: WT_INDX062020 | CZ1: WT_INDX072020 | DA1: WT_INDX082020 | DB1: WT_INDX092020 | DC1: WT_INDX102020 | DD1: WT_INDX112020 | DE1: WT_INDX122020 | DF1: WT_INDX012021 | DG1: WT_INDX022021 | DH1: WT_INDX032021 | DI1: WT_INDX042021 | DJ1: WT_INDX052021 | DK1: WT_INDX062021 | DL1: WT_INDX072021 | DM1: WT_INDX082021 | DN1: WT_INDX092021 | DO1: WT_INDX102021 | DP1: WT_INDX112021 | DQ1: WT_INDX122021 | DR1: WT_INDX012022 | DS1: WT_INDX022022 | DT1: WT_INDX032022 | DU1: WT_INDX042022 | DV1: WT_INDX052022 | DW1: WT_INDX062022 | DX1: WT_INDX072022 | DY1: WT_INDX082022 | DZ1: WT_INDX092022 | EA1: WT_INDX102022 | EB1: WT_INDX112022 | EC1: WT_INDX122022 | ED1: WT_INDX012023 | EE1: WT_INDX022023 | EF1: WT_INDX032023 | EG1: WT_INDX042023 | EH1: WT_INDX052023 | EI1: WT_INDX062023 | EJ1: WT_INDX072023 | EK1: WT_INDX082023 | EL1: WT_INDX092023 | EM1: WT_INDX102023
A2: Bajra | B2: 1101010104 | C2: 0.08637 | D2: 107.7 | E2: =IFERROR(WPI_RAW_DATA!D2*WPI_data_prepped!$C2/WPI_data_prepped!$D2,0) -> 0.08637 | F2: =IFERROR(WPI_RAW_DATA!E2*WPI_data_prepped!$C2/WPI_data_prepped!$D2,0) -> 0.08765312 | G2: =IFERROR(WPI_RAW_DATA!F2*WPI_data_prepped!$C2/WPI_data_prepped!$D2,0) -> 0.085808635 | H2: =IFERROR(WPI_RAW_DATA!G2*WPI_data_prepped!$C2/WPI_data_prepped!$D2,0) -> 0.091342089 | I2: =IFERROR(WPI_RAW_DATA!H2*WPI_data_prepped!$C2/WPI_data_prepped!$D2,0) -> 0.096795348 | J2: =IFERROR(WPI_RAW_DATA!I2*WPI_data_prepped!$C2/WPI_data_prepped!$D2,0) -> 0.097597298 | K2: =IFERROR(WPI_RAW_DATA!J2*WPI_data_prepped!$C2/WPI_data_prepped!$D2,0) -> 0.092063844 | L2: =IFERROR(WPI_RAW_DATA!K2*WPI_data_prepped!$C2/WPI_data_prepped!$D2,0) -> 0.096554763 | ... EM2: =IFERROR(WPI_RAW_DATA!EL2*WPI_data_prepped!$C2/WPI_data_prepped!$D2,0) -> 0.18565139
A3: Moong | B3: 1101010203 | C3: 0.07088 | D3: 96.3 | E3: =IFERROR(WPI_RAW_DATA!D3*WPI_data_prepped!$C3/WPI_data_prepped!$D3,0) -> 0.07088 | F3: =IFERROR(WPI_RAW_DATA!E3*WPI_data_prepped!$C3/WPI_data_prepped!$D3,0) -> 0.07065919 | G3: =IFERROR(WPI_RAW_DATA!F3*WPI_data_prepped!$C3/WPI_data_prepped!$D3,0) -> 0.07110081 | H3: =IFERROR(WPI_RAW_DATA!G3*WPI_data_prepped!$C3/WPI_data_prepped!$D3,0) -> 0.076253043 | I3: =IFERROR(WPI_RAW_DATA!H3*WPI_data_prepped!$C3/WPI_data_prepped!$D3,0) -> 0.080006812 | J3: =IFERROR(WPI_RAW_DATA!I3*WPI_data_prepped!$C3/WPI_data_prepped!$D3,0) -> 0.079786002 | K3: =IFERROR(WPI_RAW_DATA!J3*WPI_data_prepped!$C3/WPI_data_prepped!$D3,0) -> 0.082582928 | L3: =IFERROR(WPI_RAW_DATA!K3*WPI_data_prepped!$C3/WPI_data_prepped!$D3,0) -> 0.083539772 | ... EM3: =IFERROR(WPI_RAW_DATA!EL3*WPI_data_prepped!$C3/WPI_data_prepped!$D3,0) -> 0.15132843
